http://10.0.2.7:8080
Cannot connect to host 10.0.2.7:8080 ssl:default [Connect call failed ('10.0.2.7', 8080)]
Traceback (most recent call last):
  File "/home/soar/.local/lib/python3.10/site-packages/aiohttp/connector.py", line 988, in _wrap_create_connection
    return await self._loop.create_connection(*args, **kwargs)
  File "/usr/lib/python3.10/asyncio/base_events.py", line 1076, in create_connection
    raise exceptions[0]
  File "/usr/lib/python3.10/asyncio/base_events.py", line 1060, in create_connection
    sock = await self._connect_sock(
  File "/usr/lib/python3.10/asyncio/base_events.py", line 969, in _connect_sock
    await self.sock_connect(sock, address)
  File "/usr/lib/python3.10/asyncio/selector_events.py", line 501, in sock_connect
    return await fut
  File "/usr/lib/python3.10/asyncio/selector_events.py", line 541, in _sock_connect_cb
    raise OSError(err, f'Connect call failed {address}')
TimeoutError: [Errno 110] Connect call failed ('10.0.2.7', 8080)

The above exception was the direct cause of the following exception:

Traceback (most recent call last):
  File "/home/soar/Documents/github/Routing-Monitor-Docker-Request-/utils/hs_router1.py", line 367, in reverse_proxy
    async with session.post(
  File "/home/soar/.local/lib/python3.10/site-packages/aiohttp/client.py", line 1187, in __aenter__
    self._resp = await self._coro
  File "/home/soar/.local/lib/python3.10/site-packages/aiohttp/client.py", line 574, in _request
    conn = await self._connector.connect(
  File "/home/soar/.local/lib/python3.10/site-packages/aiohttp/connector.py", line 540, in connect
    proto = await self._create_connection(req, traces, timeout)
  File "/home/soar/.local/lib/python3.10/site-packages/aiohttp/connector.py", line 907, in _create_connection
    _, proto = await self._create_direct_connection(req, traces, timeout)
  File "/home/soar/.local/lib/python3.10/site-packages/aiohttp/connector.py", line 1231, in _create_direct_connection
    raise last_exc
  File "/home/soar/.local/lib/python3.10/site-packages/aiohttp/connector.py", line 1200, in _create_direct_connection
    transp, proto = await self._wrap_create_connection(
  File "/home/soar/.local/lib/python3.10/site-packages/aiohttp/connector.py", line 996, in _wrap_create_connection
    raise client_error(req.connection_key, exc) from exc
aiohttp.client_exceptions.ClientConnectorError: Cannot connect to host 10.0.2.7:8080 ssl:default [Connect call failed ('10.0.2.7', 8080)]
http://10.0.2.7:8080
Cannot connect to host 10.0.2.7:8080 ssl:default [Connect call failed ('10.0.2.7', 8080)]
Traceback (most recent call last):
  File "/home/soar/.local/lib/python3.10/site-packages/aiohttp/connector.py", line 988, in _wrap_create_connection
    return await self._loop.create_connection(*args, **kwargs)
  File "/usr/lib/python3.10/asyncio/base_events.py", line 1076, in create_connection
    raise exceptions[0]
  File "/usr/lib/python3.10/asyncio/base_events.py", line 1060, in create_connection
    sock = await self._connect_sock(
  File "/usr/lib/python3.10/asyncio/base_events.py", line 969, in _connect_sock
    await self.sock_connect(sock, address)
  File "/usr/lib/python3.10/asyncio/selector_events.py", line 501, in sock_connect
    return await fut
  File "/usr/lib/python3.10/asyncio/selector_events.py", line 541, in _sock_connect_cb
    raise OSError(err, f'Connect call failed {address}')
TimeoutError: [Errno 110] Connect call failed ('10.0.2.7', 8080)

The above exception was the direct cause of the following exception:

Traceback (most recent call last):
  File "/home/soar/Documents/github/Routing-Monitor-Docker-Request-/utils/hs_router1.py", line 367, in reverse_proxy
    async with session.post(
  File "/home/soar/.local/lib/python3.10/site-packages/aiohttp/client.py", line 1187, in __aenter__
    self._resp = await self._coro
  File "/home/soar/.local/lib/python3.10/site-packages/aiohttp/client.py", line 574, in _request
    conn = await self._connector.connect(
  File "/home/soar/.local/lib/python3.10/site-packages/aiohttp/connector.py", line 540, in connect
    proto = await self._create_connection(req, traces, timeout)
  File "/home/soar/.local/lib/python3.10/site-packages/aiohttp/connector.py", line 907, in _create_connection
    _, proto = await self._create_direct_connection(req, traces, timeout)
  File "/home/soar/.local/lib/python3.10/site-packages/aiohttp/connector.py", line 1231, in _create_direct_connection
    raise last_exc
  File "/home/soar/.local/lib/python3.10/site-packages/aiohttp/connector.py", line 1200, in _create_direct_connection
    transp, proto = await self._wrap_create_connection(
  File "/home/soar/.local/lib/python3.10/site-packages/aiohttp/connector.py", line 996, in _wrap_create_connection
    raise client_error(req.connection_key, exc) from exc
aiohttp.client_exceptions.ClientConnectorError: Cannot connect to host 10.0.2.7:8080 ssl:default [Connect call failed ('10.0.2.7', 8080)]
http://10.0.2.7:8080
'Logger' object is not callable
Traceback (most recent call last):
  File "/home/soar/Documents/github/Routing-Monitor-Docker-Request-/utils/hs_router1.py", line 366, in reverse_proxy
    runningLog(f"headers: {request.headers}")
TypeError: 'Logger' object is not callable
http://10.0.2.7:8080
'Logger' object is not callable
Traceback (most recent call last):
  File "/home/soar/Documents/github/Routing-Monitor-Docker-Request-/utils/hs_router1.py", line 366, in reverse_proxy
    runningLog(f"headers: {request.headers}")
TypeError: 'Logger' object is not callable
http://10.0.2.7:8080
'Logger' object is not callable
Traceback (most recent call last):
  File "/home/soar/Documents/github/Routing-Monitor-Docker-Request-/utils/hs_router1.py", line 366, in reverse_proxy
    runningLog(f"headers: {request.headers}")
TypeError: 'Logger' object is not callable
http://10.0.2.7:8080
Cannot connect to host 10.0.2.7:8080 ssl:default [Connect call failed ('10.0.2.7', 8080)]
Traceback (most recent call last):
  File "/home/soar/.local/lib/python3.10/site-packages/aiohttp/connector.py", line 988, in _wrap_create_connection
    return await self._loop.create_connection(*args, **kwargs)
  File "/usr/lib/python3.10/asyncio/base_events.py", line 1076, in create_connection
    raise exceptions[0]
  File "/usr/lib/python3.10/asyncio/base_events.py", line 1060, in create_connection
    sock = await self._connect_sock(
  File "/usr/lib/python3.10/asyncio/base_events.py", line 969, in _connect_sock
    await self.sock_connect(sock, address)
  File "/usr/lib/python3.10/asyncio/selector_events.py", line 501, in sock_connect
    return await fut
  File "/usr/lib/python3.10/asyncio/selector_events.py", line 541, in _sock_connect_cb
    raise OSError(err, f'Connect call failed {address}')
TimeoutError: [Errno 110] Connect call failed ('10.0.2.7', 8080)

The above exception was the direct cause of the following exception:

Traceback (most recent call last):
  File "/home/soar/Documents/github/Routing-Monitor-Docker-Request-/utils/hs_router1.py", line 367, in reverse_proxy
    async with session.post(
  File "/home/soar/.local/lib/python3.10/site-packages/aiohttp/client.py", line 1187, in __aenter__
    self._resp = await self._coro
  File "/home/soar/.local/lib/python3.10/site-packages/aiohttp/client.py", line 574, in _request
    conn = await self._connector.connect(
  File "/home/soar/.local/lib/python3.10/site-packages/aiohttp/connector.py", line 540, in connect
    proto = await self._create_connection(req, traces, timeout)
  File "/home/soar/.local/lib/python3.10/site-packages/aiohttp/connector.py", line 907, in _create_connection
    _, proto = await self._create_direct_connection(req, traces, timeout)
  File "/home/soar/.local/lib/python3.10/site-packages/aiohttp/connector.py", line 1231, in _create_direct_connection
    raise last_exc
  File "/home/soar/.local/lib/python3.10/site-packages/aiohttp/connector.py", line 1200, in _create_direct_connection
    transp, proto = await self._wrap_create_connection(
  File "/home/soar/.local/lib/python3.10/site-packages/aiohttp/connector.py", line 996, in _wrap_create_connection
    raise client_error(req.connection_key, exc) from exc
aiohttp.client_exceptions.ClientConnectorError: Cannot connect to host 10.0.2.7:8080 ssl:default [Connect call failed ('10.0.2.7', 8080)]
http://10.0.2.7:8080
Cannot connect to host 10.0.2.7:8080 ssl:default [Connect call failed ('10.0.2.7', 8080)]
Traceback (most recent call last):
  File "/home/soar/.local/lib/python3.10/site-packages/aiohttp/connector.py", line 988, in _wrap_create_connection
    return await self._loop.create_connection(*args, **kwargs)
  File "/usr/lib/python3.10/asyncio/base_events.py", line 1076, in create_connection
    raise exceptions[0]
  File "/usr/lib/python3.10/asyncio/base_events.py", line 1060, in create_connection
    sock = await self._connect_sock(
  File "/usr/lib/python3.10/asyncio/base_events.py", line 969, in _connect_sock
    await self.sock_connect(sock, address)
  File "/usr/lib/python3.10/asyncio/selector_events.py", line 501, in sock_connect
    return await fut
  File "/usr/lib/python3.10/asyncio/selector_events.py", line 541, in _sock_connect_cb
    raise OSError(err, f'Connect call failed {address}')
TimeoutError: [Errno 110] Connect call failed ('10.0.2.7', 8080)

The above exception was the direct cause of the following exception:

Traceback (most recent call last):
  File "/home/soar/Documents/github/Routing-Monitor-Docker-Request-/utils/hs_router1.py", line 368, in reverse_proxy
    async with session.post(
  File "/home/soar/.local/lib/python3.10/site-packages/aiohttp/client.py", line 1187, in __aenter__
    self._resp = await self._coro
  File "/home/soar/.local/lib/python3.10/site-packages/aiohttp/client.py", line 574, in _request
    conn = await self._connector.connect(
  File "/home/soar/.local/lib/python3.10/site-packages/aiohttp/connector.py", line 540, in connect
    proto = await self._create_connection(req, traces, timeout)
  File "/home/soar/.local/lib/python3.10/site-packages/aiohttp/connector.py", line 907, in _create_connection
    _, proto = await self._create_direct_connection(req, traces, timeout)
  File "/home/soar/.local/lib/python3.10/site-packages/aiohttp/connector.py", line 1231, in _create_direct_connection
    raise last_exc
  File "/home/soar/.local/lib/python3.10/site-packages/aiohttp/connector.py", line 1200, in _create_direct_connection
    transp, proto = await self._wrap_create_connection(
  File "/home/soar/.local/lib/python3.10/site-packages/aiohttp/connector.py", line 996, in _wrap_create_connection
    raise client_error(req.connection_key, exc) from exc
aiohttp.client_exceptions.ClientConnectorError: Cannot connect to host 10.0.2.7:8080 ssl:default [Connect call failed ('10.0.2.7', 8080)]
http://10.0.2.7:8080
Cannot connect to host 10.0.2.7:8080 ssl:default [Connect call failed ('10.0.2.7', 8080)]
Traceback (most recent call last):
  File "/home/soar/.local/lib/python3.10/site-packages/aiohttp/connector.py", line 988, in _wrap_create_connection
    return await self._loop.create_connection(*args, **kwargs)
  File "/usr/lib/python3.10/asyncio/base_events.py", line 1076, in create_connection
    raise exceptions[0]
  File "/usr/lib/python3.10/asyncio/base_events.py", line 1060, in create_connection
    sock = await self._connect_sock(
  File "/usr/lib/python3.10/asyncio/base_events.py", line 969, in _connect_sock
    await self.sock_connect(sock, address)
  File "/usr/lib/python3.10/asyncio/selector_events.py", line 501, in sock_connect
    return await fut
  File "/usr/lib/python3.10/asyncio/selector_events.py", line 541, in _sock_connect_cb
    raise OSError(err, f'Connect call failed {address}')
TimeoutError: [Errno 110] Connect call failed ('10.0.2.7', 8080)

The above exception was the direct cause of the following exception:

Traceback (most recent call last):
  File "/home/soar/Documents/github/Routing-Monitor-Docker-Request-/utils/hs_router1.py", line 368, in reverse_proxy
    async with session.post(
  File "/home/soar/.local/lib/python3.10/site-packages/aiohttp/client.py", line 1187, in __aenter__
    self._resp = await self._coro
  File "/home/soar/.local/lib/python3.10/site-packages/aiohttp/client.py", line 574, in _request
    conn = await self._connector.connect(
  File "/home/soar/.local/lib/python3.10/site-packages/aiohttp/connector.py", line 540, in connect
    proto = await self._create_connection(req, traces, timeout)
  File "/home/soar/.local/lib/python3.10/site-packages/aiohttp/connector.py", line 907, in _create_connection
    _, proto = await self._create_direct_connection(req, traces, timeout)
  File "/home/soar/.local/lib/python3.10/site-packages/aiohttp/connector.py", line 1231, in _create_direct_connection
    raise last_exc
  File "/home/soar/.local/lib/python3.10/site-packages/aiohttp/connector.py", line 1200, in _create_direct_connection
    transp, proto = await self._wrap_create_connection(
  File "/home/soar/.local/lib/python3.10/site-packages/aiohttp/connector.py", line 996, in _wrap_create_connection
    raise client_error(req.connection_key, exc) from exc
aiohttp.client_exceptions.ClientConnectorError: Cannot connect to host 10.0.2.7:8080 ssl:default [Connect call failed ('10.0.2.7', 8080)]
http://10.0.2.7:8080
Cannot connect to host 10.0.2.7:8080 ssl:default [Connect call failed ('10.0.2.7', 8080)]
Traceback (most recent call last):
  File "/home/soar/.local/lib/python3.10/site-packages/aiohttp/connector.py", line 988, in _wrap_create_connection
    return await self._loop.create_connection(*args, **kwargs)
  File "/usr/lib/python3.10/asyncio/base_events.py", line 1076, in create_connection
    raise exceptions[0]
  File "/usr/lib/python3.10/asyncio/base_events.py", line 1060, in create_connection
    sock = await self._connect_sock(
  File "/usr/lib/python3.10/asyncio/base_events.py", line 969, in _connect_sock
    await self.sock_connect(sock, address)
  File "/usr/lib/python3.10/asyncio/selector_events.py", line 501, in sock_connect
    return await fut
  File "/usr/lib/python3.10/asyncio/selector_events.py", line 541, in _sock_connect_cb
    raise OSError(err, f'Connect call failed {address}')
TimeoutError: [Errno 110] Connect call failed ('10.0.2.7', 8080)

The above exception was the direct cause of the following exception:

Traceback (most recent call last):
  File "/home/soar/Documents/github/Routing-Monitor-Docker-Request-/utils/hs_router1.py", line 368, in reverse_proxy
    async with session.post(
  File "/home/soar/.local/lib/python3.10/site-packages/aiohttp/client.py", line 1187, in __aenter__
    self._resp = await self._coro
  File "/home/soar/.local/lib/python3.10/site-packages/aiohttp/client.py", line 574, in _request
    conn = await self._connector.connect(
  File "/home/soar/.local/lib/python3.10/site-packages/aiohttp/connector.py", line 540, in connect
    proto = await self._create_connection(req, traces, timeout)
  File "/home/soar/.local/lib/python3.10/site-packages/aiohttp/connector.py", line 907, in _create_connection
    _, proto = await self._create_direct_connection(req, traces, timeout)
  File "/home/soar/.local/lib/python3.10/site-packages/aiohttp/connector.py", line 1231, in _create_direct_connection
    raise last_exc
  File "/home/soar/.local/lib/python3.10/site-packages/aiohttp/connector.py", line 1200, in _create_direct_connection
    transp, proto = await self._wrap_create_connection(
  File "/home/soar/.local/lib/python3.10/site-packages/aiohttp/connector.py", line 996, in _wrap_create_connection
    raise client_error(req.connection_key, exc) from exc
aiohttp.client_exceptions.ClientConnectorError: Cannot connect to host 10.0.2.7:8080 ssl:default [Connect call failed ('10.0.2.7', 8080)]
http://10.0.2.7:8080
Cannot connect to host 10.0.2.7:8080 ssl:default [Connect call failed ('10.0.2.7', 8080)]
Traceback (most recent call last):
  File "/home/soar/.local/lib/python3.10/site-packages/aiohttp/connector.py", line 988, in _wrap_create_connection
    return await self._loop.create_connection(*args, **kwargs)
  File "/usr/lib/python3.10/asyncio/base_events.py", line 1076, in create_connection
    raise exceptions[0]
  File "/usr/lib/python3.10/asyncio/base_events.py", line 1060, in create_connection
    sock = await self._connect_sock(
  File "/usr/lib/python3.10/asyncio/base_events.py", line 969, in _connect_sock
    await self.sock_connect(sock, address)
  File "/usr/lib/python3.10/asyncio/selector_events.py", line 501, in sock_connect
    return await fut
  File "/usr/lib/python3.10/asyncio/selector_events.py", line 541, in _sock_connect_cb
    raise OSError(err, f'Connect call failed {address}')
TimeoutError: [Errno 110] Connect call failed ('10.0.2.7', 8080)

The above exception was the direct cause of the following exception:

Traceback (most recent call last):
  File "/home/soar/Documents/github/Routing-Monitor-Docker-Request-/utils/hs_router1.py", line 368, in reverse_proxy
    async with session.post(
  File "/home/soar/.local/lib/python3.10/site-packages/aiohttp/client.py", line 1187, in __aenter__
    self._resp = await self._coro
  File "/home/soar/.local/lib/python3.10/site-packages/aiohttp/client.py", line 574, in _request
    conn = await self._connector.connect(
  File "/home/soar/.local/lib/python3.10/site-packages/aiohttp/connector.py", line 540, in connect
    proto = await self._create_connection(req, traces, timeout)
  File "/home/soar/.local/lib/python3.10/site-packages/aiohttp/connector.py", line 907, in _create_connection
    _, proto = await self._create_direct_connection(req, traces, timeout)
  File "/home/soar/.local/lib/python3.10/site-packages/aiohttp/connector.py", line 1231, in _create_direct_connection
    raise last_exc
  File "/home/soar/.local/lib/python3.10/site-packages/aiohttp/connector.py", line 1200, in _create_direct_connection
    transp, proto = await self._wrap_create_connection(
  File "/home/soar/.local/lib/python3.10/site-packages/aiohttp/connector.py", line 996, in _wrap_create_connection
    raise client_error(req.connection_key, exc) from exc
aiohttp.client_exceptions.ClientConnectorError: Cannot connect to host 10.0.2.7:8080 ssl:default [Connect call failed ('10.0.2.7', 8080)]
http://10.0.2.7:8080
Cannot connect to host 10.0.2.7:8080 ssl:default [Connect call failed ('10.0.2.7', 8080)]
Traceback (most recent call last):
  File "/home/soar/.local/lib/python3.10/site-packages/aiohttp/connector.py", line 988, in _wrap_create_connection
    return await self._loop.create_connection(*args, **kwargs)
  File "/usr/lib/python3.10/asyncio/base_events.py", line 1076, in create_connection
    raise exceptions[0]
  File "/usr/lib/python3.10/asyncio/base_events.py", line 1060, in create_connection
    sock = await self._connect_sock(
  File "/usr/lib/python3.10/asyncio/base_events.py", line 969, in _connect_sock
    await self.sock_connect(sock, address)
  File "/usr/lib/python3.10/asyncio/selector_events.py", line 501, in sock_connect
    return await fut
  File "/usr/lib/python3.10/asyncio/selector_events.py", line 541, in _sock_connect_cb
    raise OSError(err, f'Connect call failed {address}')
TimeoutError: [Errno 110] Connect call failed ('10.0.2.7', 8080)

The above exception was the direct cause of the following exception:

Traceback (most recent call last):
  File "/home/soar/Documents/github/Routing-Monitor-Docker-Request-/utils/hs_router1.py", line 368, in reverse_proxy
    async with session.post(
  File "/home/soar/.local/lib/python3.10/site-packages/aiohttp/client.py", line 1187, in __aenter__
    self._resp = await self._coro
  File "/home/soar/.local/lib/python3.10/site-packages/aiohttp/client.py", line 574, in _request
    conn = await self._connector.connect(
  File "/home/soar/.local/lib/python3.10/site-packages/aiohttp/connector.py", line 540, in connect
    proto = await self._create_connection(req, traces, timeout)
  File "/home/soar/.local/lib/python3.10/site-packages/aiohttp/connector.py", line 907, in _create_connection
    _, proto = await self._create_direct_connection(req, traces, timeout)
  File "/home/soar/.local/lib/python3.10/site-packages/aiohttp/connector.py", line 1231, in _create_direct_connection
    raise last_exc
  File "/home/soar/.local/lib/python3.10/site-packages/aiohttp/connector.py", line 1200, in _create_direct_connection
    transp, proto = await self._wrap_create_connection(
  File "/home/soar/.local/lib/python3.10/site-packages/aiohttp/connector.py", line 996, in _wrap_create_connection
    raise client_error(req.connection_key, exc) from exc
aiohttp.client_exceptions.ClientConnectorError: Cannot connect to host 10.0.2.7:8080 ssl:default [Connect call failed ('10.0.2.7', 8080)]
http://10.0.2.7:8080
Cannot connect to host 10.0.2.7:8080 ssl:default [Connect call failed ('10.0.2.7', 8080)]
Traceback (most recent call last):
  File "/home/soar/.local/lib/python3.10/site-packages/aiohttp/connector.py", line 988, in _wrap_create_connection
    return await self._loop.create_connection(*args, **kwargs)
  File "/usr/lib/python3.10/asyncio/base_events.py", line 1076, in create_connection
    raise exceptions[0]
  File "/usr/lib/python3.10/asyncio/base_events.py", line 1060, in create_connection
    sock = await self._connect_sock(
  File "/usr/lib/python3.10/asyncio/base_events.py", line 969, in _connect_sock
    await self.sock_connect(sock, address)
  File "/usr/lib/python3.10/asyncio/selector_events.py", line 501, in sock_connect
    return await fut
  File "/usr/lib/python3.10/asyncio/selector_events.py", line 541, in _sock_connect_cb
    raise OSError(err, f'Connect call failed {address}')
TimeoutError: [Errno 110] Connect call failed ('10.0.2.7', 8080)

The above exception was the direct cause of the following exception:

Traceback (most recent call last):
  File "/home/soar/Documents/github/Routing-Monitor-Docker-Request-/utils/hs_router1.py", line 368, in reverse_proxy
    async with session.post(
  File "/home/soar/.local/lib/python3.10/site-packages/aiohttp/client.py", line 1187, in __aenter__
    self._resp = await self._coro
  File "/home/soar/.local/lib/python3.10/site-packages/aiohttp/client.py", line 574, in _request
    conn = await self._connector.connect(
  File "/home/soar/.local/lib/python3.10/site-packages/aiohttp/connector.py", line 540, in connect
    proto = await self._create_connection(req, traces, timeout)
  File "/home/soar/.local/lib/python3.10/site-packages/aiohttp/connector.py", line 907, in _create_connection
    _, proto = await self._create_direct_connection(req, traces, timeout)
  File "/home/soar/.local/lib/python3.10/site-packages/aiohttp/connector.py", line 1231, in _create_direct_connection
    raise last_exc
  File "/home/soar/.local/lib/python3.10/site-packages/aiohttp/connector.py", line 1200, in _create_direct_connection
    transp, proto = await self._wrap_create_connection(
  File "/home/soar/.local/lib/python3.10/site-packages/aiohttp/connector.py", line 996, in _wrap_create_connection
    raise client_error(req.connection_key, exc) from exc
aiohttp.client_exceptions.ClientConnectorError: Cannot connect to host 10.0.2.7:8080 ssl:default [Connect call failed ('10.0.2.7', 8080)]
http://10.0.2.7:8080
Cannot connect to host 10.0.2.7:8080 ssl:default [Connect call failed ('10.0.2.7', 8080)]
Traceback (most recent call last):
  File "/home/soar/.local/lib/python3.10/site-packages/aiohttp/connector.py", line 988, in _wrap_create_connection
    return await self._loop.create_connection(*args, **kwargs)
  File "/usr/lib/python3.10/asyncio/base_events.py", line 1076, in create_connection
    raise exceptions[0]
  File "/usr/lib/python3.10/asyncio/base_events.py", line 1060, in create_connection
    sock = await self._connect_sock(
  File "/usr/lib/python3.10/asyncio/base_events.py", line 969, in _connect_sock
    await self.sock_connect(sock, address)
  File "/usr/lib/python3.10/asyncio/selector_events.py", line 501, in sock_connect
    return await fut
  File "/usr/lib/python3.10/asyncio/selector_events.py", line 541, in _sock_connect_cb
    raise OSError(err, f'Connect call failed {address}')
TimeoutError: [Errno 110] Connect call failed ('10.0.2.7', 8080)

The above exception was the direct cause of the following exception:

Traceback (most recent call last):
  File "/home/soar/Documents/github/Routing-Monitor-Docker-Request-/utils/hs_router1.py", line 368, in reverse_proxy
    async with session.post(
  File "/home/soar/.local/lib/python3.10/site-packages/aiohttp/client.py", line 1187, in __aenter__
    self._resp = await self._coro
  File "/home/soar/.local/lib/python3.10/site-packages/aiohttp/client.py", line 574, in _request
    conn = await self._connector.connect(
  File "/home/soar/.local/lib/python3.10/site-packages/aiohttp/connector.py", line 540, in connect
    proto = await self._create_connection(req, traces, timeout)
  File "/home/soar/.local/lib/python3.10/site-packages/aiohttp/connector.py", line 907, in _create_connection
    _, proto = await self._create_direct_connection(req, traces, timeout)
  File "/home/soar/.local/lib/python3.10/site-packages/aiohttp/connector.py", line 1231, in _create_direct_connection
    raise last_exc
  File "/home/soar/.local/lib/python3.10/site-packages/aiohttp/connector.py", line 1200, in _create_direct_connection
    transp, proto = await self._wrap_create_connection(
  File "/home/soar/.local/lib/python3.10/site-packages/aiohttp/connector.py", line 996, in _wrap_create_connection
    raise client_error(req.connection_key, exc) from exc
aiohttp.client_exceptions.ClientConnectorError: Cannot connect to host 10.0.2.7:8080 ssl:default [Connect call failed ('10.0.2.7', 8080)]
http://10.0.2.7:8080
Cannot connect to host 10.0.2.7:8080 ssl:default [Connect call failed ('10.0.2.7', 8080)]
Traceback (most recent call last):
  File "/home/soar/.local/lib/python3.10/site-packages/aiohttp/connector.py", line 988, in _wrap_create_connection
    return await self._loop.create_connection(*args, **kwargs)
  File "/usr/lib/python3.10/asyncio/base_events.py", line 1076, in create_connection
    raise exceptions[0]
  File "/usr/lib/python3.10/asyncio/base_events.py", line 1060, in create_connection
    sock = await self._connect_sock(
  File "/usr/lib/python3.10/asyncio/base_events.py", line 969, in _connect_sock
    await self.sock_connect(sock, address)
  File "/usr/lib/python3.10/asyncio/selector_events.py", line 501, in sock_connect
    return await fut
  File "/usr/lib/python3.10/asyncio/selector_events.py", line 541, in _sock_connect_cb
    raise OSError(err, f'Connect call failed {address}')
TimeoutError: [Errno 110] Connect call failed ('10.0.2.7', 8080)

The above exception was the direct cause of the following exception:

Traceback (most recent call last):
  File "/home/soar/Documents/github/Routing-Monitor-Docker-Request-/utils/hs_router1.py", line 368, in reverse_proxy
    async with session.post(
  File "/home/soar/.local/lib/python3.10/site-packages/aiohttp/client.py", line 1187, in __aenter__
    self._resp = await self._coro
  File "/home/soar/.local/lib/python3.10/site-packages/aiohttp/client.py", line 574, in _request
    conn = await self._connector.connect(
  File "/home/soar/.local/lib/python3.10/site-packages/aiohttp/connector.py", line 540, in connect
    proto = await self._create_connection(req, traces, timeout)
  File "/home/soar/.local/lib/python3.10/site-packages/aiohttp/connector.py", line 907, in _create_connection
    _, proto = await self._create_direct_connection(req, traces, timeout)
  File "/home/soar/.local/lib/python3.10/site-packages/aiohttp/connector.py", line 1231, in _create_direct_connection
    raise last_exc
  File "/home/soar/.local/lib/python3.10/site-packages/aiohttp/connector.py", line 1200, in _create_direct_connection
    transp, proto = await self._wrap_create_connection(
  File "/home/soar/.local/lib/python3.10/site-packages/aiohttp/connector.py", line 996, in _wrap_create_connection
    raise client_error(req.connection_key, exc) from exc
aiohttp.client_exceptions.ClientConnectorError: Cannot connect to host 10.0.2.7:8080 ssl:default [Connect call failed ('10.0.2.7', 8080)]
http://10.0.2.7:8080
Cannot connect to host 10.0.2.7:8080 ssl:default [Connect call failed ('10.0.2.7', 8080)]
Traceback (most recent call last):
  File "/home/soar/.local/lib/python3.10/site-packages/aiohttp/connector.py", line 988, in _wrap_create_connection
    return await self._loop.create_connection(*args, **kwargs)
  File "/usr/lib/python3.10/asyncio/base_events.py", line 1076, in create_connection
    raise exceptions[0]
  File "/usr/lib/python3.10/asyncio/base_events.py", line 1060, in create_connection
    sock = await self._connect_sock(
  File "/usr/lib/python3.10/asyncio/base_events.py", line 969, in _connect_sock
    await self.sock_connect(sock, address)
  File "/usr/lib/python3.10/asyncio/selector_events.py", line 501, in sock_connect
    return await fut
  File "/usr/lib/python3.10/asyncio/selector_events.py", line 541, in _sock_connect_cb
    raise OSError(err, f'Connect call failed {address}')
TimeoutError: [Errno 110] Connect call failed ('10.0.2.7', 8080)

The above exception was the direct cause of the following exception:

Traceback (most recent call last):
  File "/home/soar/Documents/github/Routing-Monitor-Docker-Request-/utils/hs_router1.py", line 368, in reverse_proxy
    async with session.post(
  File "/home/soar/.local/lib/python3.10/site-packages/aiohttp/client.py", line 1187, in __aenter__
    self._resp = await self._coro
  File "/home/soar/.local/lib/python3.10/site-packages/aiohttp/client.py", line 574, in _request
    conn = await self._connector.connect(
  File "/home/soar/.local/lib/python3.10/site-packages/aiohttp/connector.py", line 540, in connect
    proto = await self._create_connection(req, traces, timeout)
  File "/home/soar/.local/lib/python3.10/site-packages/aiohttp/connector.py", line 907, in _create_connection
    _, proto = await self._create_direct_connection(req, traces, timeout)
  File "/home/soar/.local/lib/python3.10/site-packages/aiohttp/connector.py", line 1231, in _create_direct_connection
    raise last_exc
  File "/home/soar/.local/lib/python3.10/site-packages/aiohttp/connector.py", line 1200, in _create_direct_connection
    transp, proto = await self._wrap_create_connection(
  File "/home/soar/.local/lib/python3.10/site-packages/aiohttp/connector.py", line 996, in _wrap_create_connection
    raise client_error(req.connection_key, exc) from exc
aiohttp.client_exceptions.ClientConnectorError: Cannot connect to host 10.0.2.7:8080 ssl:default [Connect call failed ('10.0.2.7', 8080)]
http://10.0.2.7:8080
Cannot connect to host 10.0.2.7:8080 ssl:default [Connect call failed ('10.0.2.7', 8080)]
Traceback (most recent call last):
  File "/home/soar/.local/lib/python3.10/site-packages/aiohttp/connector.py", line 988, in _wrap_create_connection
    return await self._loop.create_connection(*args, **kwargs)
  File "/usr/lib/python3.10/asyncio/base_events.py", line 1076, in create_connection
    raise exceptions[0]
  File "/usr/lib/python3.10/asyncio/base_events.py", line 1060, in create_connection
    sock = await self._connect_sock(
  File "/usr/lib/python3.10/asyncio/base_events.py", line 969, in _connect_sock
    await self.sock_connect(sock, address)
  File "/usr/lib/python3.10/asyncio/selector_events.py", line 501, in sock_connect
    return await fut
  File "/usr/lib/python3.10/asyncio/selector_events.py", line 541, in _sock_connect_cb
    raise OSError(err, f'Connect call failed {address}')
TimeoutError: [Errno 110] Connect call failed ('10.0.2.7', 8080)

The above exception was the direct cause of the following exception:

Traceback (most recent call last):
  File "/home/soar/Documents/github/Routing-Monitor-Docker-Request-/utils/hs_router1.py", line 368, in reverse_proxy
    async with session.post(
  File "/home/soar/.local/lib/python3.10/site-packages/aiohttp/client.py", line 1187, in __aenter__
    self._resp = await self._coro
  File "/home/soar/.local/lib/python3.10/site-packages/aiohttp/client.py", line 574, in _request
    conn = await self._connector.connect(
  File "/home/soar/.local/lib/python3.10/site-packages/aiohttp/connector.py", line 540, in connect
    proto = await self._create_connection(req, traces, timeout)
  File "/home/soar/.local/lib/python3.10/site-packages/aiohttp/connector.py", line 907, in _create_connection
    _, proto = await self._create_direct_connection(req, traces, timeout)
  File "/home/soar/.local/lib/python3.10/site-packages/aiohttp/connector.py", line 1231, in _create_direct_connection
    raise last_exc
  File "/home/soar/.local/lib/python3.10/site-packages/aiohttp/connector.py", line 1200, in _create_direct_connection
    transp, proto = await self._wrap_create_connection(
  File "/home/soar/.local/lib/python3.10/site-packages/aiohttp/connector.py", line 996, in _wrap_create_connection
    raise client_error(req.connection_key, exc) from exc
aiohttp.client_exceptions.ClientConnectorError: Cannot connect to host 10.0.2.7:8080 ssl:default [Connect call failed ('10.0.2.7', 8080)]
http://10.0.2.7:8080
Cannot connect to host 10.0.2.7:8080 ssl:default [Connect call failed ('10.0.2.7', 8080)]
Traceback (most recent call last):
  File "/home/soar/.local/lib/python3.10/site-packages/aiohttp/connector.py", line 988, in _wrap_create_connection
    return await self._loop.create_connection(*args, **kwargs)
  File "/usr/lib/python3.10/asyncio/base_events.py", line 1076, in create_connection
    raise exceptions[0]
  File "/usr/lib/python3.10/asyncio/base_events.py", line 1060, in create_connection
    sock = await self._connect_sock(
  File "/usr/lib/python3.10/asyncio/base_events.py", line 969, in _connect_sock
    await self.sock_connect(sock, address)
  File "/usr/lib/python3.10/asyncio/selector_events.py", line 501, in sock_connect
    return await fut
  File "/usr/lib/python3.10/asyncio/selector_events.py", line 541, in _sock_connect_cb
    raise OSError(err, f'Connect call failed {address}')
ConnectionRefusedError: [Errno 111] Connect call failed ('10.0.2.7', 8080)

The above exception was the direct cause of the following exception:

Traceback (most recent call last):
  File "/home/soar/Documents/github/Routing-Monitor-Docker-Request-/utils/hs_router1.py", line 368, in reverse_proxy
    async with session.post(
  File "/home/soar/.local/lib/python3.10/site-packages/aiohttp/client.py", line 1187, in __aenter__
    self._resp = await self._coro
  File "/home/soar/.local/lib/python3.10/site-packages/aiohttp/client.py", line 574, in _request
    conn = await self._connector.connect(
  File "/home/soar/.local/lib/python3.10/site-packages/aiohttp/connector.py", line 540, in connect
    proto = await self._create_connection(req, traces, timeout)
  File "/home/soar/.local/lib/python3.10/site-packages/aiohttp/connector.py", line 907, in _create_connection
    _, proto = await self._create_direct_connection(req, traces, timeout)
  File "/home/soar/.local/lib/python3.10/site-packages/aiohttp/connector.py", line 1231, in _create_direct_connection
    raise last_exc
  File "/home/soar/.local/lib/python3.10/site-packages/aiohttp/connector.py", line 1200, in _create_direct_connection
    transp, proto = await self._wrap_create_connection(
  File "/home/soar/.local/lib/python3.10/site-packages/aiohttp/connector.py", line 996, in _wrap_create_connection
    raise client_error(req.connection_key, exc) from exc
aiohttp.client_exceptions.ClientConnectorError: Cannot connect to host 10.0.2.7:8080 ssl:default [Connect call failed ('10.0.2.7', 8080)]
http://10.0.2.7:8080
Cannot connect to host 10.0.2.7:8080 ssl:default [Connect call failed ('10.0.2.7', 8080)]
Traceback (most recent call last):
  File "/home/soar/.local/lib/python3.10/site-packages/aiohttp/connector.py", line 988, in _wrap_create_connection
    return await self._loop.create_connection(*args, **kwargs)
  File "/usr/lib/python3.10/asyncio/base_events.py", line 1076, in create_connection
    raise exceptions[0]
  File "/usr/lib/python3.10/asyncio/base_events.py", line 1060, in create_connection
    sock = await self._connect_sock(
  File "/usr/lib/python3.10/asyncio/base_events.py", line 969, in _connect_sock
    await self.sock_connect(sock, address)
  File "/usr/lib/python3.10/asyncio/selector_events.py", line 501, in sock_connect
    return await fut
  File "/usr/lib/python3.10/asyncio/selector_events.py", line 541, in _sock_connect_cb
    raise OSError(err, f'Connect call failed {address}')
ConnectionRefusedError: [Errno 111] Connect call failed ('10.0.2.7', 8080)

The above exception was the direct cause of the following exception:

Traceback (most recent call last):
  File "/home/soar/Documents/github/Routing-Monitor-Docker-Request-/utils/hs_router1.py", line 368, in reverse_proxy
    async with session.post(
  File "/home/soar/.local/lib/python3.10/site-packages/aiohttp/client.py", line 1187, in __aenter__
    self._resp = await self._coro
  File "/home/soar/.local/lib/python3.10/site-packages/aiohttp/client.py", line 574, in _request
    conn = await self._connector.connect(
  File "/home/soar/.local/lib/python3.10/site-packages/aiohttp/connector.py", line 540, in connect
    proto = await self._create_connection(req, traces, timeout)
  File "/home/soar/.local/lib/python3.10/site-packages/aiohttp/connector.py", line 907, in _create_connection
    _, proto = await self._create_direct_connection(req, traces, timeout)
  File "/home/soar/.local/lib/python3.10/site-packages/aiohttp/connector.py", line 1231, in _create_direct_connection
    raise last_exc
  File "/home/soar/.local/lib/python3.10/site-packages/aiohttp/connector.py", line 1200, in _create_direct_connection
    transp, proto = await self._wrap_create_connection(
  File "/home/soar/.local/lib/python3.10/site-packages/aiohttp/connector.py", line 996, in _wrap_create_connection
    raise client_error(req.connection_key, exc) from exc
aiohttp.client_exceptions.ClientConnectorError: Cannot connect to host 10.0.2.7:8080 ssl:default [Connect call failed ('10.0.2.7', 8080)]
http://10.0.2.7:8080
Cannot connect to host 10.0.2.7:8080 ssl:default [Connect call failed ('10.0.2.7', 8080)]
Traceback (most recent call last):
  File "/home/soar/.local/lib/python3.10/site-packages/aiohttp/connector.py", line 988, in _wrap_create_connection
    return await self._loop.create_connection(*args, **kwargs)
  File "/usr/lib/python3.10/asyncio/base_events.py", line 1076, in create_connection
    raise exceptions[0]
  File "/usr/lib/python3.10/asyncio/base_events.py", line 1060, in create_connection
    sock = await self._connect_sock(
  File "/usr/lib/python3.10/asyncio/base_events.py", line 969, in _connect_sock
    await self.sock_connect(sock, address)
  File "/usr/lib/python3.10/asyncio/selector_events.py", line 501, in sock_connect
    return await fut
  File "/usr/lib/python3.10/asyncio/selector_events.py", line 541, in _sock_connect_cb
    raise OSError(err, f'Connect call failed {address}')
ConnectionRefusedError: [Errno 111] Connect call failed ('10.0.2.7', 8080)

The above exception was the direct cause of the following exception:

Traceback (most recent call last):
  File "/home/soar/Documents/github/Routing-Monitor-Docker-Request-/utils/hs_router1.py", line 368, in reverse_proxy
    async with session.post(
  File "/home/soar/.local/lib/python3.10/site-packages/aiohttp/client.py", line 1187, in __aenter__
    self._resp = await self._coro
  File "/home/soar/.local/lib/python3.10/site-packages/aiohttp/client.py", line 574, in _request
    conn = await self._connector.connect(
  File "/home/soar/.local/lib/python3.10/site-packages/aiohttp/connector.py", line 540, in connect
    proto = await self._create_connection(req, traces, timeout)
  File "/home/soar/.local/lib/python3.10/site-packages/aiohttp/connector.py", line 907, in _create_connection
    _, proto = await self._create_direct_connection(req, traces, timeout)
  File "/home/soar/.local/lib/python3.10/site-packages/aiohttp/connector.py", line 1231, in _create_direct_connection
    raise last_exc
  File "/home/soar/.local/lib/python3.10/site-packages/aiohttp/connector.py", line 1200, in _create_direct_connection
    transp, proto = await self._wrap_create_connection(
  File "/home/soar/.local/lib/python3.10/site-packages/aiohttp/connector.py", line 996, in _wrap_create_connection
    raise client_error(req.connection_key, exc) from exc
aiohttp.client_exceptions.ClientConnectorError: Cannot connect to host 10.0.2.7:8080 ssl:default [Connect call failed ('10.0.2.7', 8080)]
http://10.0.2.7:8080
Cannot connect to host 10.0.2.7:8080 ssl:default [Connect call failed ('10.0.2.7', 8080)]
Traceback (most recent call last):
  File "/home/soar/.local/lib/python3.10/site-packages/aiohttp/connector.py", line 988, in _wrap_create_connection
    return await self._loop.create_connection(*args, **kwargs)
  File "/usr/lib/python3.10/asyncio/base_events.py", line 1076, in create_connection
    raise exceptions[0]
  File "/usr/lib/python3.10/asyncio/base_events.py", line 1060, in create_connection
    sock = await self._connect_sock(
  File "/usr/lib/python3.10/asyncio/base_events.py", line 969, in _connect_sock
    await self.sock_connect(sock, address)
  File "/usr/lib/python3.10/asyncio/selector_events.py", line 501, in sock_connect
    return await fut
  File "/usr/lib/python3.10/asyncio/selector_events.py", line 541, in _sock_connect_cb
    raise OSError(err, f'Connect call failed {address}')
TimeoutError: [Errno 110] Connect call failed ('10.0.2.7', 8080)

The above exception was the direct cause of the following exception:

Traceback (most recent call last):
  File "/home/soar/Documents/github/Routing-Monitor-Docker-Request-/utils/hs_router1.py", line 368, in reverse_proxy
    async with session.post(
  File "/home/soar/.local/lib/python3.10/site-packages/aiohttp/client.py", line 1187, in __aenter__
    self._resp = await self._coro
  File "/home/soar/.local/lib/python3.10/site-packages/aiohttp/client.py", line 574, in _request
    conn = await self._connector.connect(
  File "/home/soar/.local/lib/python3.10/site-packages/aiohttp/connector.py", line 540, in connect
    proto = await self._create_connection(req, traces, timeout)
  File "/home/soar/.local/lib/python3.10/site-packages/aiohttp/connector.py", line 907, in _create_connection
    _, proto = await self._create_direct_connection(req, traces, timeout)
  File "/home/soar/.local/lib/python3.10/site-packages/aiohttp/connector.py", line 1231, in _create_direct_connection
    raise last_exc
  File "/home/soar/.local/lib/python3.10/site-packages/aiohttp/connector.py", line 1200, in _create_direct_connection
    transp, proto = await self._wrap_create_connection(
  File "/home/soar/.local/lib/python3.10/site-packages/aiohttp/connector.py", line 996, in _wrap_create_connection
    raise client_error(req.connection_key, exc) from exc
aiohttp.client_exceptions.ClientConnectorError: Cannot connect to host 10.0.2.7:8080 ssl:default [Connect call failed ('10.0.2.7', 8080)]
http://10.0.2.7:8080
Cannot connect to host 10.0.2.7:8080 ssl:default [Connect call failed ('10.0.2.7', 8080)]
Traceback (most recent call last):
  File "/home/soar/.local/lib/python3.10/site-packages/aiohttp/connector.py", line 988, in _wrap_create_connection
    return await self._loop.create_connection(*args, **kwargs)
  File "/usr/lib/python3.10/asyncio/base_events.py", line 1076, in create_connection
    raise exceptions[0]
  File "/usr/lib/python3.10/asyncio/base_events.py", line 1060, in create_connection
    sock = await self._connect_sock(
  File "/usr/lib/python3.10/asyncio/base_events.py", line 969, in _connect_sock
    await self.sock_connect(sock, address)
  File "/usr/lib/python3.10/asyncio/selector_events.py", line 501, in sock_connect
    return await fut
  File "/usr/lib/python3.10/asyncio/selector_events.py", line 541, in _sock_connect_cb
    raise OSError(err, f'Connect call failed {address}')
TimeoutError: [Errno 110] Connect call failed ('10.0.2.7', 8080)

The above exception was the direct cause of the following exception:

Traceback (most recent call last):
  File "/home/soar/Documents/github/Routing-Monitor-Docker-Request-/utils/hs_router1.py", line 368, in reverse_proxy
    async with session.post(
  File "/home/soar/.local/lib/python3.10/site-packages/aiohttp/client.py", line 1187, in __aenter__
    self._resp = await self._coro
  File "/home/soar/.local/lib/python3.10/site-packages/aiohttp/client.py", line 574, in _request
    conn = await self._connector.connect(
  File "/home/soar/.local/lib/python3.10/site-packages/aiohttp/connector.py", line 540, in connect
    proto = await self._create_connection(req, traces, timeout)
  File "/home/soar/.local/lib/python3.10/site-packages/aiohttp/connector.py", line 907, in _create_connection
    _, proto = await self._create_direct_connection(req, traces, timeout)
  File "/home/soar/.local/lib/python3.10/site-packages/aiohttp/connector.py", line 1231, in _create_direct_connection
    raise last_exc
  File "/home/soar/.local/lib/python3.10/site-packages/aiohttp/connector.py", line 1200, in _create_direct_connection
    transp, proto = await self._wrap_create_connection(
  File "/home/soar/.local/lib/python3.10/site-packages/aiohttp/connector.py", line 996, in _wrap_create_connection
    raise client_error(req.connection_key, exc) from exc
aiohttp.client_exceptions.ClientConnectorError: Cannot connect to host 10.0.2.7:8080 ssl:default [Connect call failed ('10.0.2.7', 8080)]
http://10.0.2.7:8080
Cannot connect to host 10.0.2.7:8080 ssl:default [Connect call failed ('10.0.2.7', 8080)]
Traceback (most recent call last):
  File "/home/soar/.local/lib/python3.10/site-packages/aiohttp/connector.py", line 988, in _wrap_create_connection
    return await self._loop.create_connection(*args, **kwargs)
  File "/usr/lib/python3.10/asyncio/base_events.py", line 1076, in create_connection
    raise exceptions[0]
  File "/usr/lib/python3.10/asyncio/base_events.py", line 1060, in create_connection
    sock = await self._connect_sock(
  File "/usr/lib/python3.10/asyncio/base_events.py", line 969, in _connect_sock
    await self.sock_connect(sock, address)
  File "/usr/lib/python3.10/asyncio/selector_events.py", line 501, in sock_connect
    return await fut
  File "/usr/lib/python3.10/asyncio/selector_events.py", line 541, in _sock_connect_cb
    raise OSError(err, f'Connect call failed {address}')
TimeoutError: [Errno 110] Connect call failed ('10.0.2.7', 8080)

The above exception was the direct cause of the following exception:

Traceback (most recent call last):
  File "/home/soar/Documents/github/Routing-Monitor-Docker-Request-/utils/hs_router1.py", line 368, in reverse_proxy
    async with session.post(
  File "/home/soar/.local/lib/python3.10/site-packages/aiohttp/client.py", line 1187, in __aenter__
    self._resp = await self._coro
  File "/home/soar/.local/lib/python3.10/site-packages/aiohttp/client.py", line 574, in _request
    conn = await self._connector.connect(
  File "/home/soar/.local/lib/python3.10/site-packages/aiohttp/connector.py", line 540, in connect
    proto = await self._create_connection(req, traces, timeout)
  File "/home/soar/.local/lib/python3.10/site-packages/aiohttp/connector.py", line 907, in _create_connection
    _, proto = await self._create_direct_connection(req, traces, timeout)
  File "/home/soar/.local/lib/python3.10/site-packages/aiohttp/connector.py", line 1231, in _create_direct_connection
    raise last_exc
  File "/home/soar/.local/lib/python3.10/site-packages/aiohttp/connector.py", line 1200, in _create_direct_connection
    transp, proto = await self._wrap_create_connection(
  File "/home/soar/.local/lib/python3.10/site-packages/aiohttp/connector.py", line 996, in _wrap_create_connection
    raise client_error(req.connection_key, exc) from exc
aiohttp.client_exceptions.ClientConnectorError: Cannot connect to host 10.0.2.7:8080 ssl:default [Connect call failed ('10.0.2.7', 8080)]
